2020-06-19 15:25:01,586 ERROR: Exception on /login [POST] [in /home/hp/.virtual_envs/Qaari/lib/python3.7/site-packages/flask/app.py:1892]
Traceback (most recent call last):
  File "/home/hp/.virtual_envs/Qaari/lib/python3.7/site-packages/flask/app.py", line 2447, in wsgi_app
    response = self.full_dispatch_request()
  File "/home/hp/.virtual_envs/Qaari/lib/python3.7/site-packages/flask/app.py", line 1952, in full_dispatch_request
    rv = self.handle_user_exception(e)
  File "/home/hp/.virtual_envs/Qaari/lib/python3.7/site-packages/flask/app.py", line 1821, in handle_user_exception
    reraise(exc_type, exc_value, tb)
  File "/home/hp/.virtual_envs/Qaari/lib/python3.7/site-packages/flask/_compat.py", line 39, in reraise
    raise value
  File "/home/hp/.virtual_envs/Qaari/lib/python3.7/site-packages/flask/app.py", line 1950, in full_dispatch_request
    rv = self.dispatch_request()
  File "/home/hp/.virtual_envs/Qaari/lib/python3.7/site-packages/flask/app.py", line 1936, in dispatch_request
    return self.view_functions[rule.endpoint](**req.view_args)
  File "/home/hp/Qaari/app/routes.py", line 55, in login
    return redirect(url_for(next_page))
  File "/home/hp/.virtual_envs/Qaari/lib/python3.7/site-packages/flask/helpers.py", line 370, in url_for
    return appctx.app.handle_url_build_error(error, endpoint, values)
  File "/home/hp/.virtual_envs/Qaari/lib/python3.7/site-packages/flask/app.py", line 2216, in handle_url_build_error
    reraise(exc_type, exc_value, tb)
  File "/home/hp/.virtual_envs/Qaari/lib/python3.7/site-packages/flask/_compat.py", line 39, in reraise
    raise value
  File "/home/hp/.virtual_envs/Qaari/lib/python3.7/site-packages/flask/helpers.py", line 358, in url_for
    endpoint, values, method=method, force_external=external
  File "/home/hp/.virtual_envs/Qaari/lib/python3.7/site-packages/werkzeug/routing.py", line 2179, in build
    raise BuildError(endpoint, values, method, self)
werkzeug.routing.BuildError: Could not build url for endpoint '/index'. Did you mean 'index' instead?
2020-09-21 18:29:11,319 INFO: Qaari startup [in /home/hp/Qaari/app/__init__.py:45]
2020-09-21 18:29:50,860 INFO: Qaari startup [in /home/hp/Qaari/app/__init__.py:45]
2020-09-21 18:30:10,122 ERROR: Exception on /favicon.ico [GET] [in /home/hp/.virtual_envs/Qaari/lib/python3.7/site-packages/flask/app.py:1892]
Traceback (most recent call last):
  File "/home/hp/.virtual_envs/Qaari/lib/python3.7/site-packages/flask/app.py", line 1950, in full_dispatch_request
    rv = self.dispatch_request()
  File "/home/hp/.virtual_envs/Qaari/lib/python3.7/site-packages/flask/app.py", line 1926, in dispatch_request
    self.raise_routing_exception(req)
  File "/home/hp/.virtual_envs/Qaari/lib/python3.7/site-packages/flask/app.py", line 1908, in raise_routing_exception
    raise request.routing_exception
  File "/home/hp/.virtual_envs/Qaari/lib/python3.7/site-packages/flask/ctx.py", line 350, in match_request
    result = self.url_adapter.match(return_rule=True)
  File "/home/hp/.virtual_envs/Qaari/lib/python3.7/site-packages/werkzeug/routing.py", line 1945, in match
    raise NotFound()
werkzeug.exceptions.NotFound: 404 Not Found: The requested URL was not found on the server. If you entered the URL manually please check your spelling and try again.

During handling of the above exception, another exception occurred:

Traceback (most recent call last):
  File "/home/hp/.virtual_envs/Qaari/lib/python3.7/site-packages/flask/app.py", line 2447, in wsgi_app
    response = self.full_dispatch_request()
  File "/home/hp/.virtual_envs/Qaari/lib/python3.7/site-packages/flask/app.py", line 1952, in full_dispatch_request
    rv = self.handle_user_exception(e)
  File "/home/hp/.virtual_envs/Qaari/lib/python3.7/site-packages/flask/app.py", line 1816, in handle_user_exception
    return self.handle_http_exception(e)
  File "/home/hp/.virtual_envs/Qaari/lib/python3.7/site-packages/flask/app.py", line 1744, in handle_http_exception
    return handler(e)
TypeError: not_found_error() takes 0 positional arguments but 1 was given
2020-09-21 18:30:33,692 ERROR: Exception on /favicon.ico [GET] [in /home/hp/.virtual_envs/Qaari/lib/python3.7/site-packages/flask/app.py:1892]
Traceback (most recent call last):
  File "/home/hp/.virtual_envs/Qaari/lib/python3.7/site-packages/flask/app.py", line 1950, in full_dispatch_request
    rv = self.dispatch_request()
  File "/home/hp/.virtual_envs/Qaari/lib/python3.7/site-packages/flask/app.py", line 1926, in dispatch_request
    self.raise_routing_exception(req)
  File "/home/hp/.virtual_envs/Qaari/lib/python3.7/site-packages/flask/app.py", line 1908, in raise_routing_exception
    raise request.routing_exception
  File "/home/hp/.virtual_envs/Qaari/lib/python3.7/site-packages/flask/ctx.py", line 350, in match_request
    result = self.url_adapter.match(return_rule=True)
  File "/home/hp/.virtual_envs/Qaari/lib/python3.7/site-packages/werkzeug/routing.py", line 1945, in match
    raise NotFound()
werkzeug.exceptions.NotFound: 404 Not Found: The requested URL was not found on the server. If you entered the URL manually please check your spelling and try again.

During handling of the above exception, another exception occurred:

Traceback (most recent call last):
  File "/home/hp/.virtual_envs/Qaari/lib/python3.7/site-packages/flask/app.py", line 2447, in wsgi_app
    response = self.full_dispatch_request()
  File "/home/hp/.virtual_envs/Qaari/lib/python3.7/site-packages/flask/app.py", line 1952, in full_dispatch_request
    rv = self.handle_user_exception(e)
  File "/home/hp/.virtual_envs/Qaari/lib/python3.7/site-packages/flask/app.py", line 1816, in handle_user_exception
    return self.handle_http_exception(e)
  File "/home/hp/.virtual_envs/Qaari/lib/python3.7/site-packages/flask/app.py", line 1744, in handle_http_exception
    return handler(e)
TypeError: not_found_error() takes 0 positional arguments but 1 was given
2020-09-21 18:30:35,954 ERROR: Exception on /favicon.ico [GET] [in /home/hp/.virtual_envs/Qaari/lib/python3.7/site-packages/flask/app.py:1892]
Traceback (most recent call last):
  File "/home/hp/.virtual_envs/Qaari/lib/python3.7/site-packages/flask/app.py", line 1950, in full_dispatch_request
    rv = self.dispatch_request()
  File "/home/hp/.virtual_envs/Qaari/lib/python3.7/site-packages/flask/app.py", line 1926, in dispatch_request
    self.raise_routing_exception(req)
  File "/home/hp/.virtual_envs/Qaari/lib/python3.7/site-packages/flask/app.py", line 1908, in raise_routing_exception
    raise request.routing_exception
  File "/home/hp/.virtual_envs/Qaari/lib/python3.7/site-packages/flask/ctx.py", line 350, in match_request
    result = self.url_adapter.match(return_rule=True)
  File "/home/hp/.virtual_envs/Qaari/lib/python3.7/site-packages/werkzeug/routing.py", line 1945, in match
    raise NotFound()
werkzeug.exceptions.NotFound: 404 Not Found: The requested URL was not found on the server. If you entered the URL manually please check your spelling and try again.

During handling of the above exception, another exception occurred:

Traceback (most recent call last):
  File "/home/hp/.virtual_envs/Qaari/lib/python3.7/site-packages/flask/app.py", line 2447, in wsgi_app
    response = self.full_dispatch_request()
  File "/home/hp/.virtual_envs/Qaari/lib/python3.7/site-packages/flask/app.py", line 1952, in full_dispatch_request
    rv = self.handle_user_exception(e)
  File "/home/hp/.virtual_envs/Qaari/lib/python3.7/site-packages/flask/app.py", line 1816, in handle_user_exception
    return self.handle_http_exception(e)
  File "/home/hp/.virtual_envs/Qaari/lib/python3.7/site-packages/flask/app.py", line 1744, in handle_http_exception
    return handler(e)
TypeError: not_found_error() takes 0 positional arguments but 1 was given
2020-09-21 18:31:02,090 ERROR: Exception on /favicon.ico [GET] [in /home/hp/.virtual_envs/Qaari/lib/python3.7/site-packages/flask/app.py:1892]
Traceback (most recent call last):
  File "/home/hp/.virtual_envs/Qaari/lib/python3.7/site-packages/flask/app.py", line 1950, in full_dispatch_request
    rv = self.dispatch_request()
  File "/home/hp/.virtual_envs/Qaari/lib/python3.7/site-packages/flask/app.py", line 1926, in dispatch_request
    self.raise_routing_exception(req)
  File "/home/hp/.virtual_envs/Qaari/lib/python3.7/site-packages/flask/app.py", line 1908, in raise_routing_exception
    raise request.routing_exception
  File "/home/hp/.virtual_envs/Qaari/lib/python3.7/site-packages/flask/ctx.py", line 350, in match_request
    result = self.url_adapter.match(return_rule=True)
  File "/home/hp/.virtual_envs/Qaari/lib/python3.7/site-packages/werkzeug/routing.py", line 1945, in match
    raise NotFound()
werkzeug.exceptions.NotFound: 404 Not Found: The requested URL was not found on the server. If you entered the URL manually please check your spelling and try again.

During handling of the above exception, another exception occurred:

Traceback (most recent call last):
  File "/home/hp/.virtual_envs/Qaari/lib/python3.7/site-packages/flask/app.py", line 2447, in wsgi_app
    response = self.full_dispatch_request()
  File "/home/hp/.virtual_envs/Qaari/lib/python3.7/site-packages/flask/app.py", line 1952, in full_dispatch_request
    rv = self.handle_user_exception(e)
  File "/home/hp/.virtual_envs/Qaari/lib/python3.7/site-packages/flask/app.py", line 1816, in handle_user_exception
    return self.handle_http_exception(e)
  File "/home/hp/.virtual_envs/Qaari/lib/python3.7/site-packages/flask/app.py", line 1744, in handle_http_exception
    return handler(e)
TypeError: not_found_error() takes 0 positional arguments but 1 was given
