2020-06-15 15:30:23,362 ERROR: Exception on /edit_profile [GET] [in /home/hp/.virtual_envs/Qaari/lib/python3.7/site-packages/flask/app.py:1892]
Traceback (most recent call last):
  File "/home/hp/.virtual_envs/Qaari/lib/python3.7/site-packages/flask/app.py", line 2447, in wsgi_app
    response = self.full_dispatch_request()
  File "/home/hp/.virtual_envs/Qaari/lib/python3.7/site-packages/flask/app.py", line 1952, in full_dispatch_request
    rv = self.handle_user_exception(e)
  File "/home/hp/.virtual_envs/Qaari/lib/python3.7/site-packages/flask/app.py", line 1821, in handle_user_exception
    reraise(exc_type, exc_value, tb)
  File "/home/hp/.virtual_envs/Qaari/lib/python3.7/site-packages/flask/_compat.py", line 39, in reraise
    raise value
  File "/home/hp/.virtual_envs/Qaari/lib/python3.7/site-packages/flask/app.py", line 1950, in full_dispatch_request
    rv = self.dispatch_request()
  File "/home/hp/.virtual_envs/Qaari/lib/python3.7/site-packages/flask/app.py", line 1936, in dispatch_request
    return self.view_functions[rule.endpoint](**req.view_args)
  File "/home/hp/Qaari/app/routes.py", line 70, in edit_profile
    form = EditProfileForm(current_user.username)
  File "/home/hp/.virtual_envs/Qaari/lib/python3.7/site-packages/wtforms/form.py", line 208, in __call__
    return type.__call__(cls, *args, **kwargs)
  File "/home/hp/Qaari/app/forms.py", line 36, in __init__
    super(EditProfileForm, self).__init__(*args, **kwargs)
AttributeError: 'super' object has no attribute '__intit__'
2020-06-15 15:30:30,588 INFO: Qaari startup [in /home/hp/Qaari/app/__init__.py:43]
2020-06-15 15:31:00,118 ERROR: Exception on /login [POST] [in /home/hp/.virtual_envs/Qaari/lib/python3.7/site-packages/flask/app.py:1892]
Traceback (most recent call last):
  File "/home/hp/.virtual_envs/Qaari/lib/python3.7/site-packages/flask/app.py", line 2447, in wsgi_app
    response = self.full_dispatch_request()
  File "/home/hp/.virtual_envs/Qaari/lib/python3.7/site-packages/flask/app.py", line 1952, in full_dispatch_request
    rv = self.handle_user_exception(e)
  File "/home/hp/.virtual_envs/Qaari/lib/python3.7/site-packages/flask/app.py", line 1821, in handle_user_exception
    reraise(exc_type, exc_value, tb)
  File "/home/hp/.virtual_envs/Qaari/lib/python3.7/site-packages/flask/_compat.py", line 39, in reraise
    raise value
  File "/home/hp/.virtual_envs/Qaari/lib/python3.7/site-packages/flask/app.py", line 1950, in full_dispatch_request
    rv = self.dispatch_request()
  File "/home/hp/.virtual_envs/Qaari/lib/python3.7/site-packages/flask/app.py", line 1936, in dispatch_request
    return self.view_functions[rule.endpoint](**req.view_args)
  File "/home/hp/Qaari/app/routes.py", line 36, in login
    return redirect(url_for(next_page))
  File "/home/hp/.virtual_envs/Qaari/lib/python3.7/site-packages/flask/helpers.py", line 370, in url_for
    return appctx.app.handle_url_build_error(error, endpoint, values)
  File "/home/hp/.virtual_envs/Qaari/lib/python3.7/site-packages/flask/app.py", line 2216, in handle_url_build_error
    reraise(exc_type, exc_value, tb)
  File "/home/hp/.virtual_envs/Qaari/lib/python3.7/site-packages/flask/_compat.py", line 39, in reraise
    raise value
  File "/home/hp/.virtual_envs/Qaari/lib/python3.7/site-packages/flask/helpers.py", line 358, in url_for
    endpoint, values, method=method, force_external=external
  File "/home/hp/.virtual_envs/Qaari/lib/python3.7/site-packages/werkzeug/routing.py", line 2179, in build
    raise BuildError(endpoint, values, method, self)
werkzeug.routing.BuildError: Could not build url for endpoint '/index'. Did you mean 'index' instead?
2020-06-15 15:56:03,700 INFO: Qaari startup [in /home/hp/Qaari/app/__init__.py:43]
2020-06-15 16:00:08,558 INFO: Qaari startup [in /home/hp/Qaari/app/__init__.py:43]
2020-06-15 16:00:44,643 INFO: Qaari startup [in /home/hp/Qaari/app/__init__.py:43]
2020-06-15 16:50:26,577 INFO: Qaari startup [in /home/hp/Qaari/app/__init__.py:43]
2020-06-15 16:50:49,324 INFO: Qaari startup [in /home/hp/Qaari/app/__init__.py:43]
2020-06-15 16:53:33,566 INFO: Qaari startup [in /home/hp/Qaari/app/__init__.py:43]
2020-06-15 16:54:31,483 INFO: Qaari startup [in /home/hp/Qaari/app/__init__.py:43]
2020-06-15 17:31:39,491 INFO: Qaari startup [in /home/hp/Qaari/app/__init__.py:43]
2020-06-15 17:32:09,639 INFO: Qaari startup [in /home/hp/Qaari/app/__init__.py:43]
2020-06-15 17:32:29,122 INFO: Qaari startup [in /home/hp/Qaari/app/__init__.py:43]
2020-06-15 17:34:27,475 INFO: Qaari startup [in /home/hp/Qaari/app/__init__.py:43]
2020-06-15 17:35:04,893 ERROR: Exception on /follow/abc [POST] [in /home/hp/.virtual_envs/Qaari/lib/python3.7/site-packages/flask/app.py:1892]
Traceback (most recent call last):
  File "/home/hp/.virtual_envs/Qaari/lib/python3.7/site-packages/flask/app.py", line 2447, in wsgi_app
    response = self.full_dispatch_request()
  File "/home/hp/.virtual_envs/Qaari/lib/python3.7/site-packages/flask/app.py", line 1952, in full_dispatch_request
    rv = self.handle_user_exception(e)
  File "/home/hp/.virtual_envs/Qaari/lib/python3.7/site-packages/flask/app.py", line 1821, in handle_user_exception
    reraise(exc_type, exc_value, tb)
  File "/home/hp/.virtual_envs/Qaari/lib/python3.7/site-packages/flask/_compat.py", line 39, in reraise
    raise value
  File "/home/hp/.virtual_envs/Qaari/lib/python3.7/site-packages/flask/app.py", line 1950, in full_dispatch_request
    rv = self.dispatch_request()
  File "/home/hp/.virtual_envs/Qaari/lib/python3.7/site-packages/flask/app.py", line 1936, in dispatch_request
    return self.view_functions[rule.endpoint](**req.view_args)
  File "/home/hp/.virtual_envs/Qaari/lib/python3.7/site-packages/flask_login/utils.py", line 272, in decorated_view
    return func(*args, **kwargs)
  File "/home/hp/Qaari/app/routes.py", line 88, in follow
    if form.validate_on_submit():
TypeError: validate_on_submit() missing 1 required positional argument: 'self'
2020-06-15 17:35:55,628 ERROR: Exception on /follow/abc [POST] [in /home/hp/.virtual_envs/Qaari/lib/python3.7/site-packages/flask/app.py:1892]
Traceback (most recent call last):
  File "/home/hp/.virtual_envs/Qaari/lib/python3.7/site-packages/flask/app.py", line 2447, in wsgi_app
    response = self.full_dispatch_request()
  File "/home/hp/.virtual_envs/Qaari/lib/python3.7/site-packages/flask/app.py", line 1952, in full_dispatch_request
    rv = self.handle_user_exception(e)
  File "/home/hp/.virtual_envs/Qaari/lib/python3.7/site-packages/flask/app.py", line 1821, in handle_user_exception
    reraise(exc_type, exc_value, tb)
  File "/home/hp/.virtual_envs/Qaari/lib/python3.7/site-packages/flask/_compat.py", line 39, in reraise
    raise value
  File "/home/hp/.virtual_envs/Qaari/lib/python3.7/site-packages/flask/app.py", line 1950, in full_dispatch_request
    rv = self.dispatch_request()
  File "/home/hp/.virtual_envs/Qaari/lib/python3.7/site-packages/flask/app.py", line 1936, in dispatch_request
    return self.view_functions[rule.endpoint](**req.view_args)
  File "/home/hp/.virtual_envs/Qaari/lib/python3.7/site-packages/flask_login/utils.py", line 272, in decorated_view
    return func(*args, **kwargs)
  File "/home/hp/Qaari/app/routes.py", line 88, in follow
    if form.validate_on_submit():
TypeError: validate_on_submit() missing 1 required positional argument: 'self'
2020-06-15 17:36:05,834 INFO: Qaari startup [in /home/hp/Qaari/app/__init__.py:43]
