2020-06-16 21:38:40,485 ERROR: Exception on /index [GET] [in /home/hp/.virtual_envs/Qaari/lib/python3.7/site-packages/flask/app.py:1892]
Traceback (most recent call last):
  File "/home/hp/.virtual_envs/Qaari/lib/python3.7/site-packages/flask/app.py", line 2447, in wsgi_app
    response = self.full_dispatch_request()
  File "/home/hp/.virtual_envs/Qaari/lib/python3.7/site-packages/flask/app.py", line 1952, in full_dispatch_request
    rv = self.handle_user_exception(e)
  File "/home/hp/.virtual_envs/Qaari/lib/python3.7/site-packages/flask/app.py", line 1821, in handle_user_exception
    reraise(exc_type, exc_value, tb)
  File "/home/hp/.virtual_envs/Qaari/lib/python3.7/site-packages/flask/_compat.py", line 39, in reraise
    raise value
  File "/home/hp/.virtual_envs/Qaari/lib/python3.7/site-packages/flask/app.py", line 1950, in full_dispatch_request
    rv = self.dispatch_request()
  File "/home/hp/.virtual_envs/Qaari/lib/python3.7/site-packages/flask/app.py", line 1936, in dispatch_request
    return self.view_functions[rule.endpoint](**req.view_args)
  File "/home/hp/.virtual_envs/Qaari/lib/python3.7/site-packages/flask_login/utils.py", line 272, in decorated_view
    return func(*args, **kwargs)
  File "/home/hp/Qaari/app/routes.py", line 32, in index
    page, app.config['POST_PER_PAGE'], False)
KeyError: 'POST_PER_PAGE'
2020-06-16 21:38:41,953 ERROR: Exception on /index [GET] [in /home/hp/.virtual_envs/Qaari/lib/python3.7/site-packages/flask/app.py:1892]
Traceback (most recent call last):
  File "/home/hp/.virtual_envs/Qaari/lib/python3.7/site-packages/flask/app.py", line 2447, in wsgi_app
    response = self.full_dispatch_request()
  File "/home/hp/.virtual_envs/Qaari/lib/python3.7/site-packages/flask/app.py", line 1952, in full_dispatch_request
    rv = self.handle_user_exception(e)
  File "/home/hp/.virtual_envs/Qaari/lib/python3.7/site-packages/flask/app.py", line 1821, in handle_user_exception
    reraise(exc_type, exc_value, tb)
  File "/home/hp/.virtual_envs/Qaari/lib/python3.7/site-packages/flask/_compat.py", line 39, in reraise
    raise value
  File "/home/hp/.virtual_envs/Qaari/lib/python3.7/site-packages/flask/app.py", line 1950, in full_dispatch_request
    rv = self.dispatch_request()
  File "/home/hp/.virtual_envs/Qaari/lib/python3.7/site-packages/flask/app.py", line 1936, in dispatch_request
    return self.view_functions[rule.endpoint](**req.view_args)
  File "/home/hp/.virtual_envs/Qaari/lib/python3.7/site-packages/flask_login/utils.py", line 272, in decorated_view
    return func(*args, **kwargs)
  File "/home/hp/Qaari/app/routes.py", line 32, in index
    page, app.config['POST_PER_PAGE'], False)
KeyError: 'POST_PER_PAGE'
2020-06-16 21:39:21,092 INFO: Qaari startup [in /home/hp/Qaari/app/__init__.py:43]
2020-06-16 21:48:58,889 INFO: Qaari startup [in /home/hp/Qaari/app/__init__.py:43]
2020-06-16 21:49:10,107 ERROR: Exception on /index [GET] [in /home/hp/.virtual_envs/Qaari/lib/python3.7/site-packages/flask/app.py:1892]
Traceback (most recent call last):
  File "/home/hp/.virtual_envs/Qaari/lib/python3.7/site-packages/flask/app.py", line 2447, in wsgi_app
    response = self.full_dispatch_request()
  File "/home/hp/.virtual_envs/Qaari/lib/python3.7/site-packages/flask/app.py", line 1952, in full_dispatch_request
    rv = self.handle_user_exception(e)
  File "/home/hp/.virtual_envs/Qaari/lib/python3.7/site-packages/flask/app.py", line 1821, in handle_user_exception
    reraise(exc_type, exc_value, tb)
  File "/home/hp/.virtual_envs/Qaari/lib/python3.7/site-packages/flask/_compat.py", line 39, in reraise
    raise value
  File "/home/hp/.virtual_envs/Qaari/lib/python3.7/site-packages/flask/app.py", line 1950, in full_dispatch_request
    rv = self.dispatch_request()
  File "/home/hp/.virtual_envs/Qaari/lib/python3.7/site-packages/flask/app.py", line 1936, in dispatch_request
    return self.view_functions[rule.endpoint](**req.view_args)
  File "/home/hp/.virtual_envs/Qaari/lib/python3.7/site-packages/flask_login/utils.py", line 272, in decorated_view
    return func(*args, **kwargs)
  File "/home/hp/Qaari/app/routes.py", line 39, in index
    prev_url=prev_url)
  File "/home/hp/.virtual_envs/Qaari/lib/python3.7/site-packages/flask/templating.py", line 138, in render_template
    ctx.app.jinja_env.get_or_select_template(template_name_or_list),
  File "/home/hp/.virtual_envs/Qaari/lib/python3.7/site-packages/jinja2/environment.py", line 930, in get_or_select_template
    return self.get_template(template_name_or_list, parent, globals)
  File "/home/hp/.virtual_envs/Qaari/lib/python3.7/site-packages/jinja2/environment.py", line 883, in get_template
    return self._load_template(name, self.make_globals(globals))
  File "/home/hp/.virtual_envs/Qaari/lib/python3.7/site-packages/jinja2/environment.py", line 857, in _load_template
    template = self.loader.load(self, name, globals)
  File "/home/hp/.virtual_envs/Qaari/lib/python3.7/site-packages/jinja2/loaders.py", line 127, in load
    code = environment.compile(source, name, filename)
  File "/home/hp/.virtual_envs/Qaari/lib/python3.7/site-packages/jinja2/environment.py", line 638, in compile
    self.handle_exception(source=source_hint)
  File "/home/hp/.virtual_envs/Qaari/lib/python3.7/site-packages/jinja2/environment.py", line 832, in handle_exception
    reraise(*rewrite_traceback_stack(source=source))
  File "/home/hp/.virtual_envs/Qaari/lib/python3.7/site-packages/jinja2/_compat.py", line 28, in reraise
    raise value.with_traceback(tb)
  File "/home/hp/Qaari/app/templates/index.html", line 26, in template
    {% endif % }
jinja2.exceptions.TemplateSyntaxError: expected token 'end of statement block', got '%'
2020-06-16 21:49:33,258 INFO: Qaari startup [in /home/hp/Qaari/app/__init__.py:43]
2020-06-16 21:51:02,665 ERROR: Exception on /login [POST] [in /home/hp/.virtual_envs/Qaari/lib/python3.7/site-packages/flask/app.py:1892]
Traceback (most recent call last):
  File "/home/hp/.virtual_envs/Qaari/lib/python3.7/site-packages/flask/app.py", line 2447, in wsgi_app
    response = self.full_dispatch_request()
  File "/home/hp/.virtual_envs/Qaari/lib/python3.7/site-packages/flask/app.py", line 1952, in full_dispatch_request
    rv = self.handle_user_exception(e)
  File "/home/hp/.virtual_envs/Qaari/lib/python3.7/site-packages/flask/app.py", line 1821, in handle_user_exception
    reraise(exc_type, exc_value, tb)
  File "/home/hp/.virtual_envs/Qaari/lib/python3.7/site-packages/flask/_compat.py", line 39, in reraise
    raise value
  File "/home/hp/.virtual_envs/Qaari/lib/python3.7/site-packages/flask/app.py", line 1950, in full_dispatch_request
    rv = self.dispatch_request()
  File "/home/hp/.virtual_envs/Qaari/lib/python3.7/site-packages/flask/app.py", line 1936, in dispatch_request
    return self.view_functions[rule.endpoint](**req.view_args)
  File "/home/hp/Qaari/app/routes.py", line 55, in login
    return redirect(url_for(next_page))
  File "/home/hp/.virtual_envs/Qaari/lib/python3.7/site-packages/flask/helpers.py", line 370, in url_for
    return appctx.app.handle_url_build_error(error, endpoint, values)
  File "/home/hp/.virtual_envs/Qaari/lib/python3.7/site-packages/flask/app.py", line 2216, in handle_url_build_error
    reraise(exc_type, exc_value, tb)
  File "/home/hp/.virtual_envs/Qaari/lib/python3.7/site-packages/flask/_compat.py", line 39, in reraise
    raise value
  File "/home/hp/.virtual_envs/Qaari/lib/python3.7/site-packages/flask/helpers.py", line 358, in url_for
    endpoint, values, method=method, force_external=external
  File "/home/hp/.virtual_envs/Qaari/lib/python3.7/site-packages/werkzeug/routing.py", line 2179, in build
    raise BuildError(endpoint, values, method, self)
werkzeug.routing.BuildError: Could not build url for endpoint '/index'. Did you mean 'index' instead?
2020-06-16 22:07:18,732 INFO: Qaari startup [in /home/hp/Qaari/app/__init__.py:43]
2020-06-16 22:07:24,030 ERROR: Exception on /user/harami [GET] [in /home/hp/.virtual_envs/Qaari/lib/python3.7/site-packages/flask/app.py:1892]
Traceback (most recent call last):
  File "/home/hp/.virtual_envs/Qaari/lib/python3.7/site-packages/flask/app.py", line 2447, in wsgi_app
    response = self.full_dispatch_request()
  File "/home/hp/.virtual_envs/Qaari/lib/python3.7/site-packages/flask/app.py", line 1952, in full_dispatch_request
    rv = self.handle_user_exception(e)
  File "/home/hp/.virtual_envs/Qaari/lib/python3.7/site-packages/flask/app.py", line 1821, in handle_user_exception
    reraise(exc_type, exc_value, tb)
  File "/home/hp/.virtual_envs/Qaari/lib/python3.7/site-packages/flask/_compat.py", line 39, in reraise
    raise value
  File "/home/hp/.virtual_envs/Qaari/lib/python3.7/site-packages/flask/app.py", line 1950, in full_dispatch_request
    rv = self.dispatch_request()
  File "/home/hp/.virtual_envs/Qaari/lib/python3.7/site-packages/flask/app.py", line 1936, in dispatch_request
    return self.view_functions[rule.endpoint](**req.view_args)
  File "/home/hp/.virtual_envs/Qaari/lib/python3.7/site-packages/flask_login/utils.py", line 272, in decorated_view
    return func(*args, **kwargs)
  File "/home/hp/Qaari/app/routes.py", line 81, in user
    page = request.args.get.filter_by('page', 1, type=int)
AttributeError: 'function' object has no attribute 'filter_by'
2020-06-16 22:08:29,489 INFO: Qaari startup [in /home/hp/Qaari/app/__init__.py:43]
