2020-09-22 20:20:31,317 ERROR: Exception on /favicon.ico [GET] [in /home/hp/.virtual_envs/Qaari/lib/python3.7/site-packages/flask/app.py:1892]
Traceback (most recent call last):
  File "/home/hp/.virtual_envs/Qaari/lib/python3.7/site-packages/flask/app.py", line 2447, in wsgi_app
    response = self.full_dispatch_request()
  File "/home/hp/.virtual_envs/Qaari/lib/python3.7/site-packages/flask/app.py", line 1952, in full_dispatch_request
    rv = self.handle_user_exception(e)
  File "/home/hp/.virtual_envs/Qaari/lib/python3.7/site-packages/flask/app.py", line 1821, in handle_user_exception
    reraise(exc_type, exc_value, tb)
  File "/home/hp/.virtual_envs/Qaari/lib/python3.7/site-packages/flask/_compat.py", line 39, in reraise
    raise value
  File "/home/hp/.virtual_envs/Qaari/lib/python3.7/site-packages/flask/app.py", line 1948, in full_dispatch_request
    rv = self.preprocess_request()
  File "/home/hp/.virtual_envs/Qaari/lib/python3.7/site-packages/flask/app.py", line 2242, in preprocess_request
    rv = func()
  File "/home/hp/Qaari/app/main/routes.py", line 16, in before_request
    g.locale = str(get_locale())
NameError: name 'get_locale' is not defined
2020-09-22 20:21:17,752 INFO: Qaari startup [in /home/hp/Qaari/app/__init__.py:71]
2020-09-22 20:21:22,794 ERROR: Exception on / [GET] [in /home/hp/.virtual_envs/Qaari/lib/python3.7/site-packages/flask/app.py:1892]
Traceback (most recent call last):
  File "/home/hp/.virtual_envs/Qaari/lib/python3.7/site-packages/flask/app.py", line 2447, in wsgi_app
    response = self.full_dispatch_request()
  File "/home/hp/.virtual_envs/Qaari/lib/python3.7/site-packages/flask/app.py", line 1952, in full_dispatch_request
    rv = self.handle_user_exception(e)
  File "/home/hp/.virtual_envs/Qaari/lib/python3.7/site-packages/flask/app.py", line 1821, in handle_user_exception
    reraise(exc_type, exc_value, tb)
  File "/home/hp/.virtual_envs/Qaari/lib/python3.7/site-packages/flask/_compat.py", line 39, in reraise
    raise value
  File "/home/hp/.virtual_envs/Qaari/lib/python3.7/site-packages/flask/app.py", line 1950, in full_dispatch_request
    rv = self.dispatch_request()
  File "/home/hp/.virtual_envs/Qaari/lib/python3.7/site-packages/flask/app.py", line 1936, in dispatch_request
    return self.view_functions[rule.endpoint](**req.view_args)
  File "/home/hp/.virtual_envs/Qaari/lib/python3.7/site-packages/flask_login/utils.py", line 272, in decorated_view
    return func(*args, **kwargs)
  File "/home/hp/Qaari/app/main/routes.py", line 38, in index
    return render_template('index.html', title=_('Home'), form=form,
NameError: name '_' is not defined
2020-09-22 20:21:53,053 ERROR: Exception on / [GET] [in /home/hp/.virtual_envs/Qaari/lib/python3.7/site-packages/flask/app.py:1892]
Traceback (most recent call last):
  File "/home/hp/.virtual_envs/Qaari/lib/python3.7/site-packages/flask/app.py", line 2447, in wsgi_app
    response = self.full_dispatch_request()
  File "/home/hp/.virtual_envs/Qaari/lib/python3.7/site-packages/flask/app.py", line 1952, in full_dispatch_request
    rv = self.handle_user_exception(e)
  File "/home/hp/.virtual_envs/Qaari/lib/python3.7/site-packages/flask/app.py", line 1821, in handle_user_exception
    reraise(exc_type, exc_value, tb)
  File "/home/hp/.virtual_envs/Qaari/lib/python3.7/site-packages/flask/_compat.py", line 39, in reraise
    raise value
  File "/home/hp/.virtual_envs/Qaari/lib/python3.7/site-packages/flask/app.py", line 1950, in full_dispatch_request
    rv = self.dispatch_request()
  File "/home/hp/.virtual_envs/Qaari/lib/python3.7/site-packages/flask/app.py", line 1936, in dispatch_request
    return self.view_functions[rule.endpoint](**req.view_args)
  File "/home/hp/.virtual_envs/Qaari/lib/python3.7/site-packages/flask_login/utils.py", line 272, in decorated_view
    return func(*args, **kwargs)
  File "/home/hp/Qaari/app/main/routes.py", line 38, in index
    return render_template('index.html', title=('Home'), form=form,
NameError: name '_' is not defined
2020-09-22 20:22:15,313 INFO: Qaari startup [in /home/hp/Qaari/app/__init__.py:71]
2020-09-22 20:22:42,066 ERROR: Exception on /explore [GET] [in /home/hp/.virtual_envs/Qaari/lib/python3.7/site-packages/flask/app.py:1892]
Traceback (most recent call last):
  File "/home/hp/.virtual_envs/Qaari/lib/python3.7/site-packages/flask/app.py", line 2447, in wsgi_app
    response = self.full_dispatch_request()
  File "/home/hp/.virtual_envs/Qaari/lib/python3.7/site-packages/flask/app.py", line 1952, in full_dispatch_request
    rv = self.handle_user_exception(e)
  File "/home/hp/.virtual_envs/Qaari/lib/python3.7/site-packages/flask/app.py", line 1821, in handle_user_exception
    reraise(exc_type, exc_value, tb)
  File "/home/hp/.virtual_envs/Qaari/lib/python3.7/site-packages/flask/_compat.py", line 39, in reraise
    raise value
  File "/home/hp/.virtual_envs/Qaari/lib/python3.7/site-packages/flask/app.py", line 1950, in full_dispatch_request
    rv = self.dispatch_request()
  File "/home/hp/.virtual_envs/Qaari/lib/python3.7/site-packages/flask/app.py", line 1936, in dispatch_request
    return self.view_functions[rule.endpoint](**req.view_args)
  File "/home/hp/.virtual_envs/Qaari/lib/python3.7/site-packages/flask_login/utils.py", line 272, in decorated_view
    return func(*args, **kwargs)
  File "/home/hp/Qaari/app/main/routes.py", line 53, in explore
    return render_template('index.html', title=_('Explore'),
NameError: name '_' is not defined
2020-09-22 20:23:40,076 ERROR: Exception on /explore [GET] [in /home/hp/.virtual_envs/Qaari/lib/python3.7/site-packages/flask/app.py:1892]
Traceback (most recent call last):
  File "/home/hp/.virtual_envs/Qaari/lib/python3.7/site-packages/flask/app.py", line 2447, in wsgi_app
    response = self.full_dispatch_request()
  File "/home/hp/.virtual_envs/Qaari/lib/python3.7/site-packages/flask/app.py", line 1952, in full_dispatch_request
    rv = self.handle_user_exception(e)
  File "/home/hp/.virtual_envs/Qaari/lib/python3.7/site-packages/flask/app.py", line 1821, in handle_user_exception
    reraise(exc_type, exc_value, tb)
  File "/home/hp/.virtual_envs/Qaari/lib/python3.7/site-packages/flask/_compat.py", line 39, in reraise
    raise value
  File "/home/hp/.virtual_envs/Qaari/lib/python3.7/site-packages/flask/app.py", line 1950, in full_dispatch_request
    rv = self.dispatch_request()
  File "/home/hp/.virtual_envs/Qaari/lib/python3.7/site-packages/flask/app.py", line 1936, in dispatch_request
    return self.view_functions[rule.endpoint](**req.view_args)
  File "/home/hp/.virtual_envs/Qaari/lib/python3.7/site-packages/flask_login/utils.py", line 272, in decorated_view
    return func(*args, **kwargs)
  File "/home/hp/Qaari/app/main/routes.py", line 53, in explore
    return render_template('index.html', title=('Explore'),
NameError: name '_' is not defined
2020-09-22 20:23:49,935 INFO: Qaari startup [in /home/hp/Qaari/app/__init__.py:71]
2020-09-22 20:26:00,563 INFO: Qaari startup [in /home/hp/Qaari/app/__init__.py:71]
2020-09-24 21:51:24,243 INFO: Qaari startup [in /home/hp/Qaari/app/__init__.py:71]
2020-09-24 23:40:59,312 INFO: Qaari startup [in /home/hp/Qaari/app/__init__.py:78]
2020-09-25 00:12:49,017 INFO: Qaari startup [in /home/hp/Qaari/app/__init__.py:78]
2020-09-25 00:16:30,433 ERROR: Exception on /unfollow/Surbhi [POST] [in /home/hp/.virtual_envs/Qaari/lib/python3.7/site-packages/flask/app.py:1892]
Traceback (most recent call last):
  File "/home/hp/.virtual_envs/Qaari/lib/python3.7/site-packages/flask/app.py", line 2447, in wsgi_app
    response = self.full_dispatch_request()
  File "/home/hp/.virtual_envs/Qaari/lib/python3.7/site-packages/flask/app.py", line 1952, in full_dispatch_request
    rv = self.handle_user_exception(e)
  File "/home/hp/.virtual_envs/Qaari/lib/python3.7/site-packages/flask/app.py", line 1821, in handle_user_exception
    reraise(exc_type, exc_value, tb)
  File "/home/hp/.virtual_envs/Qaari/lib/python3.7/site-packages/flask/_compat.py", line 39, in reraise
    raise value
  File "/home/hp/.virtual_envs/Qaari/lib/python3.7/site-packages/flask/app.py", line 1950, in full_dispatch_request
    rv = self.dispatch_request()
  File "/home/hp/.virtual_envs/Qaari/lib/python3.7/site-packages/flask/app.py", line 1936, in dispatch_request
    return self.view_functions[rule.endpoint](**req.view_args)
  File "/home/hp/.virtual_envs/Qaari/lib/python3.7/site-packages/flask_login/utils.py", line 272, in decorated_view
    return func(*args, **kwargs)
  File "/home/hp/Qaari/app/main/routes.py", line 125, in unfollow
    flash('You are not following %(username)s.', username=username)
TypeError: flash() got an unexpected keyword argument 'username'
2020-09-25 00:33:48,185 INFO: Qaari startup [in /home/hp/Qaari/app/__init__.py:78]
2020-09-25 00:34:27,994 ERROR: Exception on /follow/Surbhi [POST] [in /home/hp/.virtual_envs/Qaari/lib/python3.7/site-packages/flask/app.py:1892]
Traceback (most recent call last):
  File "/home/hp/.virtual_envs/Qaari/lib/python3.7/site-packages/flask/app.py", line 2447, in wsgi_app
    response = self.full_dispatch_request()
  File "/home/hp/.virtual_envs/Qaari/lib/python3.7/site-packages/flask/app.py", line 1952, in full_dispatch_request
    rv = self.handle_user_exception(e)
  File "/home/hp/.virtual_envs/Qaari/lib/python3.7/site-packages/flask/app.py", line 1821, in handle_user_exception
    reraise(exc_type, exc_value, tb)
  File "/home/hp/.virtual_envs/Qaari/lib/python3.7/site-packages/flask/_compat.py", line 39, in reraise
    raise value
  File "/home/hp/.virtual_envs/Qaari/lib/python3.7/site-packages/flask/app.py", line 1950, in full_dispatch_request
    rv = self.dispatch_request()
  File "/home/hp/.virtual_envs/Qaari/lib/python3.7/site-packages/flask/app.py", line 1936, in dispatch_request
    return self.view_functions[rule.endpoint](**req.view_args)
  File "/home/hp/.virtual_envs/Qaari/lib/python3.7/site-packages/flask_login/utils.py", line 272, in decorated_view
    return func(*args, **kwargs)
  File "/home/hp/Qaari/app/main/routes.py", line 105, in follow
    flash('You are following %(username)s!', username=username)
TypeError: flash() got an unexpected keyword argument 'username'
