2020-09-21 18:34:29,765 ERROR: Exception on /favicon.ico [GET] [in /home/hp/.virtual_envs/Qaari/lib/python3.7/site-packages/flask/app.py:1892]
Traceback (most recent call last):
  File "/home/hp/.virtual_envs/Qaari/lib/python3.7/site-packages/flask/app.py", line 1950, in full_dispatch_request
    rv = self.dispatch_request()
  File "/home/hp/.virtual_envs/Qaari/lib/python3.7/site-packages/flask/app.py", line 1926, in dispatch_request
    self.raise_routing_exception(req)
  File "/home/hp/.virtual_envs/Qaari/lib/python3.7/site-packages/flask/app.py", line 1908, in raise_routing_exception
    raise request.routing_exception
  File "/home/hp/.virtual_envs/Qaari/lib/python3.7/site-packages/flask/ctx.py", line 350, in match_request
    result = self.url_adapter.match(return_rule=True)
  File "/home/hp/.virtual_envs/Qaari/lib/python3.7/site-packages/werkzeug/routing.py", line 1945, in match
    raise NotFound()
werkzeug.exceptions.NotFound: 404 Not Found: The requested URL was not found on the server. If you entered the URL manually please check your spelling and try again.

During handling of the above exception, another exception occurred:

Traceback (most recent call last):
  File "/home/hp/.virtual_envs/Qaari/lib/python3.7/site-packages/flask/app.py", line 2447, in wsgi_app
    response = self.full_dispatch_request()
  File "/home/hp/.virtual_envs/Qaari/lib/python3.7/site-packages/flask/app.py", line 1952, in full_dispatch_request
    rv = self.handle_user_exception(e)
  File "/home/hp/.virtual_envs/Qaari/lib/python3.7/site-packages/flask/app.py", line 1816, in handle_user_exception
    return self.handle_http_exception(e)
  File "/home/hp/.virtual_envs/Qaari/lib/python3.7/site-packages/flask/app.py", line 1744, in handle_http_exception
    return handler(e)
TypeError: not_found_error() takes 0 positional arguments but 1 was given
2020-09-21 18:34:31,452 ERROR: Exception on /favicon.ico [GET] [in /home/hp/.virtual_envs/Qaari/lib/python3.7/site-packages/flask/app.py:1892]
Traceback (most recent call last):
  File "/home/hp/.virtual_envs/Qaari/lib/python3.7/site-packages/flask/app.py", line 1950, in full_dispatch_request
    rv = self.dispatch_request()
  File "/home/hp/.virtual_envs/Qaari/lib/python3.7/site-packages/flask/app.py", line 1926, in dispatch_request
    self.raise_routing_exception(req)
  File "/home/hp/.virtual_envs/Qaari/lib/python3.7/site-packages/flask/app.py", line 1908, in raise_routing_exception
    raise request.routing_exception
  File "/home/hp/.virtual_envs/Qaari/lib/python3.7/site-packages/flask/ctx.py", line 350, in match_request
    result = self.url_adapter.match(return_rule=True)
  File "/home/hp/.virtual_envs/Qaari/lib/python3.7/site-packages/werkzeug/routing.py", line 1945, in match
    raise NotFound()
werkzeug.exceptions.NotFound: 404 Not Found: The requested URL was not found on the server. If you entered the URL manually please check your spelling and try again.

During handling of the above exception, another exception occurred:

Traceback (most recent call last):
  File "/home/hp/.virtual_envs/Qaari/lib/python3.7/site-packages/flask/app.py", line 2447, in wsgi_app
    response = self.full_dispatch_request()
  File "/home/hp/.virtual_envs/Qaari/lib/python3.7/site-packages/flask/app.py", line 1952, in full_dispatch_request
    rv = self.handle_user_exception(e)
  File "/home/hp/.virtual_envs/Qaari/lib/python3.7/site-packages/flask/app.py", line 1816, in handle_user_exception
    return self.handle_http_exception(e)
  File "/home/hp/.virtual_envs/Qaari/lib/python3.7/site-packages/flask/app.py", line 1744, in handle_http_exception
    return handler(e)
TypeError: not_found_error() takes 0 positional arguments but 1 was given
2020-09-21 18:34:36,090 ERROR: Exception on /favicon.ico [GET] [in /home/hp/.virtual_envs/Qaari/lib/python3.7/site-packages/flask/app.py:1892]
Traceback (most recent call last):
  File "/home/hp/.virtual_envs/Qaari/lib/python3.7/site-packages/flask/app.py", line 1950, in full_dispatch_request
    rv = self.dispatch_request()
  File "/home/hp/.virtual_envs/Qaari/lib/python3.7/site-packages/flask/app.py", line 1926, in dispatch_request
    self.raise_routing_exception(req)
  File "/home/hp/.virtual_envs/Qaari/lib/python3.7/site-packages/flask/app.py", line 1908, in raise_routing_exception
    raise request.routing_exception
  File "/home/hp/.virtual_envs/Qaari/lib/python3.7/site-packages/flask/ctx.py", line 350, in match_request
    result = self.url_adapter.match(return_rule=True)
  File "/home/hp/.virtual_envs/Qaari/lib/python3.7/site-packages/werkzeug/routing.py", line 1945, in match
    raise NotFound()
werkzeug.exceptions.NotFound: 404 Not Found: The requested URL was not found on the server. If you entered the URL manually please check your spelling and try again.

During handling of the above exception, another exception occurred:

Traceback (most recent call last):
  File "/home/hp/.virtual_envs/Qaari/lib/python3.7/site-packages/flask/app.py", line 2447, in wsgi_app
    response = self.full_dispatch_request()
  File "/home/hp/.virtual_envs/Qaari/lib/python3.7/site-packages/flask/app.py", line 1952, in full_dispatch_request
    rv = self.handle_user_exception(e)
  File "/home/hp/.virtual_envs/Qaari/lib/python3.7/site-packages/flask/app.py", line 1816, in handle_user_exception
    return self.handle_http_exception(e)
  File "/home/hp/.virtual_envs/Qaari/lib/python3.7/site-packages/flask/app.py", line 1744, in handle_http_exception
    return handler(e)
TypeError: not_found_error() takes 0 positional arguments but 1 was given
2020-09-21 18:34:40,232 ERROR: Exception on /favicon.ico [GET] [in /home/hp/.virtual_envs/Qaari/lib/python3.7/site-packages/flask/app.py:1892]
Traceback (most recent call last):
  File "/home/hp/.virtual_envs/Qaari/lib/python3.7/site-packages/flask/app.py", line 1950, in full_dispatch_request
    rv = self.dispatch_request()
  File "/home/hp/.virtual_envs/Qaari/lib/python3.7/site-packages/flask/app.py", line 1926, in dispatch_request
    self.raise_routing_exception(req)
  File "/home/hp/.virtual_envs/Qaari/lib/python3.7/site-packages/flask/app.py", line 1908, in raise_routing_exception
    raise request.routing_exception
  File "/home/hp/.virtual_envs/Qaari/lib/python3.7/site-packages/flask/ctx.py", line 350, in match_request
    result = self.url_adapter.match(return_rule=True)
  File "/home/hp/.virtual_envs/Qaari/lib/python3.7/site-packages/werkzeug/routing.py", line 1945, in match
    raise NotFound()
werkzeug.exceptions.NotFound: 404 Not Found: The requested URL was not found on the server. If you entered the URL manually please check your spelling and try again.

During handling of the above exception, another exception occurred:

Traceback (most recent call last):
  File "/home/hp/.virtual_envs/Qaari/lib/python3.7/site-packages/flask/app.py", line 2447, in wsgi_app
    response = self.full_dispatch_request()
  File "/home/hp/.virtual_envs/Qaari/lib/python3.7/site-packages/flask/app.py", line 1952, in full_dispatch_request
    rv = self.handle_user_exception(e)
  File "/home/hp/.virtual_envs/Qaari/lib/python3.7/site-packages/flask/app.py", line 1816, in handle_user_exception
    return self.handle_http_exception(e)
  File "/home/hp/.virtual_envs/Qaari/lib/python3.7/site-packages/flask/app.py", line 1744, in handle_http_exception
    return handler(e)
TypeError: not_found_error() takes 0 positional arguments but 1 was given
2020-09-21 18:34:45,441 ERROR: Exception on /favicon.ico [GET] [in /home/hp/.virtual_envs/Qaari/lib/python3.7/site-packages/flask/app.py:1892]
Traceback (most recent call last):
  File "/home/hp/.virtual_envs/Qaari/lib/python3.7/site-packages/flask/app.py", line 1950, in full_dispatch_request
    rv = self.dispatch_request()
  File "/home/hp/.virtual_envs/Qaari/lib/python3.7/site-packages/flask/app.py", line 1926, in dispatch_request
    self.raise_routing_exception(req)
  File "/home/hp/.virtual_envs/Qaari/lib/python3.7/site-packages/flask/app.py", line 1908, in raise_routing_exception
    raise request.routing_exception
  File "/home/hp/.virtual_envs/Qaari/lib/python3.7/site-packages/flask/ctx.py", line 350, in match_request
    result = self.url_adapter.match(return_rule=True)
  File "/home/hp/.virtual_envs/Qaari/lib/python3.7/site-packages/werkzeug/routing.py", line 1945, in match
    raise NotFound()
werkzeug.exceptions.NotFound: 404 Not Found: The requested URL was not found on the server. If you entered the URL manually please check your spelling and try again.

During handling of the above exception, another exception occurred:

Traceback (most recent call last):
  File "/home/hp/.virtual_envs/Qaari/lib/python3.7/site-packages/flask/app.py", line 2447, in wsgi_app
    response = self.full_dispatch_request()
  File "/home/hp/.virtual_envs/Qaari/lib/python3.7/site-packages/flask/app.py", line 1952, in full_dispatch_request
    rv = self.handle_user_exception(e)
  File "/home/hp/.virtual_envs/Qaari/lib/python3.7/site-packages/flask/app.py", line 1816, in handle_user_exception
    return self.handle_http_exception(e)
  File "/home/hp/.virtual_envs/Qaari/lib/python3.7/site-packages/flask/app.py", line 1744, in handle_http_exception
    return handler(e)
TypeError: not_found_error() takes 0 positional arguments but 1 was given
